<?xml version="1.0" ?>
<!-- =================================================================================== -->
<!-- |    This document was autogenerated by xacro from RH-P12-RN/rh_p12_rn_description/urdf/rh_p12_rn.xacro | -->
<!-- |    EDITING THIS FILE BY HAND IS NOT RECOMMENDED                                 | -->
<!-- =================================================================================== -->
<robot name="rh_p12_rn" xmlns:xacro="http://www.ros.org/wiki/xacro">
  <!-- ros_control plugin -->
  <gazebo>
    <plugin filename="libgazebo_ros_control.so" name="gazebo_ros_control">
      <robotNamespace>/rh_p12_rn</robotNamespace>
      <robotSimType>gazebo_ros_control/DefaultRobotHWSim</robotSimType>
      <legacyModeNS>true</legacyModeNS>
    </plugin>
  </gazebo>
  <!-- World -->
  <gazebo reference="world">
  </gazebo>
  <!-- rh_p12_rn_base -->
  <gazebo reference="rh_p12_rn_base">
    <mu1>0.2</mu1>
    <mu2>0.2</mu2>
    <material>Gazebo/Grey</material>
  </gazebo>
  <!-- rh_p12_rn_r1 -->
  <gazebo reference="rh_p12_rn_r1">
    <mu1>0.2</mu1>
    <mu2>0.2</mu2>
    <material>Gazebo/Grey</material>
  </gazebo>
  <!-- rh_p12_rn_r2 -->
  <gazebo reference="rh_p12_rn_r2">
    <mu1>0.2</mu1>
    <mu2>0.2</mu2>
    <material>Gazebo/Grey</material>
  </gazebo>
  <!-- rh_p12_rn_l1 -->
  <gazebo reference="rh_p12_rn_l1">
    <mu1>0.2</mu1>
    <mu2>0.2</mu2>
    <material>Gazebo/Grey</material>
  </gazebo>
  <!-- rh_p12_rn_l2 -->
  <gazebo reference="rh_p12_rn_l2">
    <mu1>0.2</mu1>
    <mu2>0.2</mu2>
    <material>Gazebo/Grey</material>
  </gazebo>
  <material name="black">
    <color rgba="0.0 0.0 0.0 1.0"/>
  </material>
  <material name="blue">
    <color rgba="0.0 0.0 0.8 1.0"/>
  </material>
  <material name="green">
    <color rgba="0.0 0.8 0.0 1.0"/>
  </material>
  <material name="grey">
    <color rgba="0.2 0.2 0.2 1.0"/>
  </material>
  <material name="orange">
    <color rgba="1.0 0.4235294117647059 0.0392156862745098 1.0"/>
  </material>
  <material name="brown">
    <color rgba="0.8705882352941177 0.8117647058823529 0.7647058823529411 1.0"/>
  </material>
  <material name="red">
    <color rgba="0.8 0.0 0.0 1.0"/>
  </material>
  <material name="white">
    <color rgba="1.0 1.0 1.0 1.0"/>
  </material>
  <!-- base -->
  <link name="rh_p12_rn_base">
    <collision>
      <origin rpy="0 0 0" xyz="0 0 0"/>
      <geometry>
        <mesh filename="package://rh_p12_rn_description/meshes/base.stl" scale="0.001 0.001 0.001"/>
      </geometry>
    </collision>
    <visual>
      <origin rpy="0 0 0" xyz="0 0 0"/>
      <geometry>
        <mesh filename="package://rh_p12_rn_description/meshes/base.stl" scale="0.001 0.001 0.001"/>
      </geometry>
      <material name="grey"/>
    </visual>
    <inertial>
      <origin rpy="0 0 0" xyz="0.000 0.000 0.032"/>
      <mass value="0.236"/>
      <!--<inertia ixx="0.00017" ixy="0.0" ixz="0.0" iyy="0.00011" iyz="0.0" izz="0.00017" />-->
      <inertia ixx="1.0" ixy="0.0" ixz="0.0" iyy="1.0" iyz="0.0" izz="1.0"/>
    </inertial>
  </link>
  <!-- Joint -->
  <joint name="rh_r1" type="revolute">
    <parent link="rh_p12_rn_base"/>
    <child link="rh_p12_rn_r1"/>
    <origin rpy="0 0 0" xyz="0.0 0.008 0.048"/>
    <axis xyz="1 0 0"/>
    <limit effort="20" lower="0.0" upper="1.1" velocity="6.5"/>
    <!-- <dynamics damping="0.7"/> -->
  </joint>
  <transmission name="tran_r1">
    <type>transmission_interface/SimpleTransmission</type>
    <joint name="rh_r1">
      <hardwareInterface>hardware_interface/EffortJointInterface</hardwareInterface>
    </joint>
    <actuator name="motor_r1">
      <hardwareInterface>hardware_interface/EffortJointInterface</hardwareInterface>
      <mechanicalReduction>1</mechanicalReduction>
    </actuator>
  </transmission>
  <!-- rh_p12_rn_r1 -->
  <link name="rh_p12_rn_r1">
    <collision>
      <origin rpy="0 0 0" xyz="0 0 0"/>
      <geometry>
        <mesh filename="package://rh_p12_rn_description/meshes/r1.stl" scale="0.001 0.001 0.001"/>
      </geometry>
    </collision>
    <visual>
      <origin rpy="0 0 0" xyz="0 0 0"/>
      <geometry>
        <mesh filename="package://rh_p12_rn_description/meshes/r1.stl" scale="0.001 0.001 0.001"/>
      </geometry>
      <material name="grey"/>
    </visual>
    <inertial>
      <origin rpy="0 0 0" xyz="0.000 0.034 0.004"/>
      <mass value="0.068"/>
      <!--<inertia ixx="0.00004" ixy="0.0" ixz="0.0" iyy="0.00002" iyz="-0.00001" izz="0.00002" />-->
      <inertia ixx="1.0" ixy="0.0" ixz="0.0" iyy="1.0" iyz="0.0" izz="1.0"/>
    </inertial>
  </link>
  <!-- Right Joint 2 -->
  <joint name="rh_r2" type="fixed">
    <parent link="rh_p12_rn_r1"/>
    <child link="rh_p12_rn_r2"/>
    <origin rpy="-0.75 0 0" xyz="0.0 0.0493634 0.0285"/>
    <!-- <origin rpy="0 0 0" xyz="0.0 0.0493634 0.0285"/> -->
    <axis xyz="-1 0 0"/>
    <limit effort="20" lower="0.0" upper="1.0" velocity="6.5"/>
    <!-- <dynamics damping="0.7"/> -->
  </joint>
  <transmission name="tran_r2">
    <type>transmission_interface/SimpleTransmission</type>
    <joint name="rh_r2">
      <hardwareInterface>hardware_interface/EffortJointInterface</hardwareInterface>
    </joint>
    <actuator name="motor_r2">
      <hardwareInterface>hardware_interface/EffortJointInterface</hardwareInterface>
      <mechanicalReduction>1</mechanicalReduction>
    </actuator>
  </transmission>
  <!-- rh_p12_rn_r2 -->
  <link name="rh_p12_rn_r2">
    <collision>
      <origin rpy="0 0 0" xyz="0 0 0"/>
      <geometry>
        <mesh filename="package://rh_p12_rn_description/meshes/r2.stl" scale="0.001 0.001 0.001"/>
      </geometry>
    </collision>
    <visual>
      <origin rpy="0 0 0" xyz="0 0 0"/>
      <geometry>
        <mesh filename="package://rh_p12_rn_description/meshes/r2.stl" scale="0.001 0.001 0.001"/>
      </geometry>
      <material name="grey"/>
    </visual>
    <inertial>
      <origin rpy="0 0 0" xyz="0.000 0.006 0.011"/>
      <mass value="0.022"/>
      <!--<inertia ixx="0.0" ixy="0.0" ixz="0.0" iyy="0.00001" iyz="0.0" izz="0.0" />-->
      <inertia ixx="1.0" ixy="0.0" ixz="0.0" iyy="1.0" iyz="0.0" izz="1.0"/>
    </inertial>
  </link>
  <!-- Left Joint 1 -->
  <joint name="rh_l1" type="revolute">
    <parent link="rh_p12_rn_base"/>
    <child link="rh_p12_rn_l1"/>
    <origin rpy="0 0 0" xyz="0.0 -0.008 0.048"/>
    <axis xyz="-1 0 0"/>
    <limit effort="20" lower="0.0" upper="1.1" velocity="6.5"/>
    <!-- <dynamics damping="0.7"/> -->
  </joint>
  <transmission name="tran_l1">
    <type>transmission_interface/SimpleTransmission</type>
    <joint name="rh_l1">
      <hardwareInterface>hardware_interface/EffortJointInterface</hardwareInterface>
    </joint>
    <actuator name="motor_l1">
      <hardwareInterface>hardware_interface/EffortJointInterface</hardwareInterface>
      <mechanicalReduction>1</mechanicalReduction>
    </actuator>
  </transmission>
  <!-- rh_p12_rn_l1 -->
  <link name="rh_p12_rn_l1">
    <collision>
      <origin rpy="0 0 0" xyz="0 0 0"/>
      <geometry>
        <mesh filename="package://rh_p12_rn_description/meshes/l1.stl" scale="0.001 0.001 0.001"/>
      </geometry>
    </collision>
    <visual>
      <origin rpy="0 0 0" xyz="0 0 0"/>
      <geometry>
        <mesh filename="package://rh_p12_rn_description/meshes/l1.stl" scale="0.001 0.001 0.001"/>
      </geometry>
      <material name="grey"/>
    </visual>
    <inertial>
      <origin rpy="0 0 0" xyz="0.000 -0.034 0.004"/>
      <mass value="0.068"/>
      <!--<inertia ixx="0.00004" ixy="0.0" ixz="0.0" iyy="0.00002" iyz="0.00001" izz="0.00002" />-->
      <inertia ixx="1.0" ixy="0.0" ixz="0.0" iyy="1.0" iyz="0.0" izz="1.0"/>
    </inertial>
  </link>
  <!-- Left Joint 2 -->
  <joint name="rh_l2" type="fixed">
    <parent link="rh_p12_rn_l1"/>
    <child link="rh_p12_rn_l2"/>
    <origin rpy="0.75 0 0" xyz="0.0 -0.0493634 0.0285"/>
    <!-- <origin rpy="0 0 0" xyz="0.0 -0.0493634 0.0285"/> -->
    <axis xyz="1 0 0"/>
    <limit effort="20" lower="0.0" upper="1.0" velocity="6.5"/>
    <!-- <dynamics damping="0.7"/> -->
  </joint>
  <transmission name="tran_l2">
    <type>transmission_interface/SimpleTransmission</type>
    <joint name="rh_l2">
      <hardwareInterface>hardware_interface/EffortJointInterface</hardwareInterface>
    </joint>
    <actuator name="motor_l2">
      <hardwareInterface>hardware_interface/EffortJointInterface</hardwareInterface>
      <mechanicalReduction>1</mechanicalReduction>
    </actuator>
  </transmission>
  <!-- rh_p12_rn_l2 -->
  <link name="rh_p12_rn_l2">
    <collision>
      <origin rpy="0 0 0" xyz="0 0 0"/>
      <geometry>
        <mesh filename="package://rh_p12_rn_description/meshes/l2.stl" scale="0.001 0.001 0.001"/>
      </geometry>
    </collision>
    <visual>
      <origin rpy="0 0 0" xyz="0 0 0"/>
      <geometry>
        <mesh filename="package://rh_p12_rn_description/meshes/l2.stl" scale="0.001 0.001 0.001"/>
      </geometry>
      <material name="grey"/>
    </visual>
    <inertial>
      <origin rpy="0 0 0" xyz="0.000 -0.006 0.011"/>
      <mass value="0.022"/>
      <!--<inertia ixx="0.0" ixy="0.0" ixz="0.0" iyy="0.00001" iyz="0.0" izz="0.0" />-->
      <inertia ixx="1.0" ixy="0.0" ixz="0.0" iyy="1.0" iyz="0.0" izz="1.0"/>
    </inertial>
  </link>
</robot>

